Workbook

Sheet order_details
A1: order_details_id | B1: order_id | C1: order_date | D1: order_time | E1: hour_order | F1: item_id | G1: item_name | H1: category | I1: price
A2: 1 | B2: 1 | C2: 44927 | D2: 0.48513889 | E2: =TEXT(Table1[[#This Row],[order_time]],"HH") -> 11 | F2: 109 | G2: =_xlfn.XLOOKUP(F2,menu_items!$A$1:$A$33,menu_items!$B$1:$B$33,,0,1) -> Korean Beef Bowl | H2: =_xlfn.XLOOKUP(F2,menu_items!$A$1:$A$33,menu_items!$C$1:$C$33,,0,1) -> Asian | I2: =_xlfn.XLOOKUP(F2,menu_items!$A$1:$A$33,menu_items!$D$1:$D$33,,0,1) -> 17.95
A3: 2 | B3: 2 | C3: 44927 | D3: 0.49837963 | E3: =TEXT(Table1[[#This Row],[order_time]],"HH") -> 11 | F3: 108 | G3: =_xlfn.XLOOKUP(F3,menu_items!$A$1:$A$33,menu_items!$B$1:$B$33,,0,1) -> Tofu Pad Thai | H3: =_xlfn.XLOOKUP(F3,menu_items!$A$1:$A$33,menu_items!$C$1:$C$33,,0,1) -> Asian | I3: =_xlfn.XLOOKUP(F3,menu_items!$A$1:$A$33,menu_items!$D$1:$D$33,,0,1) -> 14.5
A4: 3 | B4: 2 | C4: 44927 | D4: 0.49837963 | E4: =TEXT(Table1[[#This Row],[order_time]],"HH") -> 11 | F4: 124 | G4: =_xlfn.XLOOKUP(F4,menu_items!$A$1:$A$33,menu_items!$B$1:$B$33,,0,1) -> Spaghetti | H4: =_xlfn.XLOOKUP(F4,menu_items!$A$1:$A$33,menu_items!$C$1:$C$33,,0,1) -> Italian | I4: =_xlfn.XLOOKUP(F4,menu_items!$A$1:$A$33,menu_items!$D$1:$D$33,,0,1) -> 14.5
A5: 4 | B5: 2 | C5: 44927 | D5: 0.49837963 | E5: =TEXT(Table1[[#This Row],[order_time]],"HH") -> 11 | F5: 117 | G5: =_xlfn.XLOOKUP(F5,menu_items!$A$1:$A$33,menu_items!$B$1:$B$33,,0,1) -> Chicken Burrito | H5: =_xlfn.XLOOKUP(F5,menu_items!$A$1:$A$33,menu_items!$C$1:$C$33,,0,1) -> Mexican | I5: =_xlfn.XLOOKUP(F5,menu_items!$A$1:$A$33,menu_items!$D$1:$D$33,,0,1) -> 12.95
A6: 5 | B6: 2 | C6: 44927 | D6: 0.49837963 | E6: =TEXT(Table1[[#This Row],[order_time]],"HH") -> 11 | F6: 129 | G6: =_xlfn.XLOOKUP(F6,menu_items!$A$1:$A$33,menu_items!$B$1:$B$33,,0,1) -> Mushroom Ravioli | H6: =_xlfn.XLOOKUP(F6,menu_items!$A$1:$A$33,menu_items!$C$1:$C$33,,0,1) -> Italian | I6: =_xlfn.XLOOKUP(F6,menu_items!$A$1:$A$33,menu_items!$D$1:$D$33,,0,1) -> 15.5
A7: 6 | B7: 2 | C7: 44927 | D7: 0.49837963 | E7: =TEXT(Table1[[#This Row],[order_time]],"HH") -> 11 | F7: 106 | G7: =_xlfn.XLOOKUP(F7,menu_items!$A$1:$A$33,menu_items!$B$1:$B$33,,0,1) -> French Fries | H7: =_xlfn.XLOOKUP(F7,menu_items!$A$1:$A$33,menu_items!$C$1:$C$33,,0,1) -> American | I7: =_xlfn.XLOOKUP(F7,menu_items!$A$1:$A$33,menu_items!$D$1:$D$33,,0,1) -> 7
A8: 7 | B8: 3 | C8: 44927 | D8: 0.50865741 | E8: =TEXT(Table1[[#This Row],[order_time]],"HH") -> 12 | F8: 117 | G8: =_xlfn.XLOOKUP(F8,menu_items!$A$1:$A$33,menu_items!$B$1:$B$33,,0,1) -> Chicken Burrito | H8: =_xlfn.XLOOKUP(F8,menu_items!$A$1:$A$33,menu_items!$C$1:$C$33,,0,1) -> Mexican | I8: =_xlfn.XLOOKUP(F8,menu_items!$A$1:$A$33,menu_items!$D$1:$D$33,,0,1) -> 12.95
A9: 8 | B9: 3 | C9: 44927 | D9: 0.50865741 | E9: =TEXT(Table1[[#This Row],[order_time]],"HH") -> 12 | F9: 119 | G9: =_xlfn.XLOOKUP(F9,menu_items!$A$1:$A$33,menu_items!$B$1:$B$33,,0,1) -> Chicken Torta | H9: =_xlfn.XLOOKUP(F9,menu_items!$A$1:$A$33,menu_items!$C$1:$C$33,,0,1) -> Mexican | I9: =_xlfn.XLOOKUP(F9,menu_items!$A$1:$A$33,menu_items!$D$1:$D$33,,0,1) -> 11.95
A10: 9 | B10: 4 | C10: 44927 | D10: 0.51146991 | E10: =TEXT(Table1[[#This Row],[order_time]],"HH") -> 12 | F10: 117 | G10: =_xlfn.XLOOKUP(F10,menu_items!$A$1:$A$33,menu_items!$B$1:$B$33,,0,1) -> Chicken Burrito | H10: =_xlfn.XLOOKUP(F10,menu_items!$A$1:$A$33,menu_items!$C$1:$C$33,,0,1) -> Mexican | I10: =_xlfn.XLOOKUP(F10,menu_items!$A$1:$A$33,menu_items!$D$1:$D$33,,0,1) -> 12.95
A11: 10 | B11: 5 | C11: 44927 | D11: 0.51493056 | E11: =TEXT(Table1[[#This Row],[order_time]],"HH") -> 12 | F11: 117 | G11: =_xlfn.XLOOKUP(F11,menu_items!$A$1:$A$33,menu_items!$B$1:$B$33,,0,1) -> Chicken Burrito | H11: =_xlfn.XLOOKUP(F11,menu_items!$A$1:$A$33,menu_items!$C$1:$C$33,,0,1) -> Mexican | I11: =_xlfn.XLOOKUP(F11,menu_items!$A$1:$A$33,menu_items!$D$1:$D$33,,0,1) -> 12.95
A12: 11 | B12: 6 | C12: 44927 | D12: 0.52055556 | E12: =TEXT(Table1[[#This Row],[order_time]],"HH") -> 12 | F12: 101 | G12: =_xlfn.XLOOKUP(F12,menu_items!$A$1:$A$33,menu_items!$B$1:$B$33,,0,1) -> Hamburger | H12: =_xlfn.XLOOKUP(F12,menu_items!$A$1:$A$33,menu_items!$C$1:$C$33,,0,1) -> American | I12: =_xlfn.XLOOKUP(F12,menu_items!$A$1:$A$33,menu_items!$D$1:$D$33,,0,1) -> 12.95
A13: 12 | B13: 6 | C13: 44927 | D13: 0.52055556 | E13: =TEXT(Table1[[#This Row],[order_time]],"HH") -> 12 | F13: 114 | G13: =_xlfn.XLOOKUP(F13,menu_items!$A$1:$A$33,menu_items!$B$1:$B$33,,0,1) -> Potstickers | H13: =_xlfn.XLOOKUP(F13,menu_items!$A$1:$A$33,menu_items!$C$1:$C$33,,0,1) -> Asian | I13: =_xlfn.XLOOKUP(F13,menu_items!$A$1:$A$33,menu_items!$D$1:$D$33,,0,1) -> 9
... A122: 121 | B122: 49 | C122: 44927 | D122: 0.77291667 | E122: =TEXT(Table1[[#This Row],[order_time]],"HH") -> 18 | F122: 120 | G122: =_xlfn.XLOOKUP(F122,menu_items!$A$1:$A$33,menu_items!$B$1:$B$33,,0,1) -> Steak Torta | H122: =_xlfn.XLOOKUP(F122,menu_items!$A$1:$A$33,menu_items!$C$1:$C$33,,0,1) -> Mexican | I122: =_xlfn.XLOOKUP(F122,menu_items!$A$1:$A$33,menu_items!$D$1:$D$33,,0,1) -> 13.95
A123: 122 | B123: 50 | C123: 44927 | D123: 0.7784838 | E123: =TEXT(Table1[[#This Row],[order_time]],"HH") -> 18 | F123: NULL | G123: =_xlfn.XLOOKUP(F123,menu_items!$A$1:$A$33,menu_items!$B$1:$B$33,,0,1) -> #N/A | H123: =_xlfn.XLOOKUP(F123,menu_items!$A$1:$A$33,menu_items!$C$1:$C$33,,0,1) -> #N/A | I123: =_xlfn.XLOOKUP(F123,menu_items!$A$1:$A$33,menu_items!$D$1:$D$33,,0,1) -> #N/A
A124: 123 | B124: 51 | C124: 44927 | D124: 0.78365741 | E124: =TEXT(Table1[[#This Row],[order_time]],"HH") -> 18 | F124: 101 | G124: =_xlfn.XLOOKUP(F124,menu_items!$A$1:$A$33,menu_items!$B$1:$B$33,,0,1) -> Hamburger | H124: =_xlfn.XLOOKUP(F124,menu_items!$A$1:$A$33,menu_items!$C$1:$C$33,,0,1) -> American | I124: =_xlfn.XLOOKUP(F124,menu_items!$A$1:$A$33,menu_items!$D$1:$D$33,,0,1) -> 12.95
A125: 124 | B125: 51 | C125: 44927 | D125: 0.78365741 | E125: =TEXT(Table1[[#This Row],[order_time]],"HH") -> 18 | F125: 112 | G125: =_xlfn.XLOOKUP(F125,menu_items!$A$1:$A$33,menu_items!$B$1:$B$33,,0,1) -> Salmon Roll | H125: =_xlfn.XLOOKUP(F125,menu_items!$A$1:$A$33,menu_items!$C$1:$C$33,,0,1) -> Asian | I125: =_xlfn.XLOOKUP(F125,menu_items!$A$1:$A$33,menu_items!$D$1:$D$33,,0,1) -> 14.95
A126: 125 | B126: 52 | C126: 44927 | D126: 0.7868287 | E126: =TEXT(Table1[[#This Row],[order_time]],"HH") -> 18 | F126: 109 | G126: =_xlfn.XLOOKUP(F126,menu_items!$A$1:$A$33,menu_items!$B$1:$B$33,,0,1) -> Korean Beef Bowl | H126: =_xlfn.XLOOKUP(F126,menu_items!$A$1:$A$33,menu_items!$C$1:$C$33,,0,1) -> Asian | I126: =_xlfn.XLOOKUP(F126,menu_items!$A$1:$A$33,menu_items!$D$1:$D$33,,0,1) -> 17.95
A127: 126 | B127: 52 | C127: 44927 | D127: 0.7868287 | E127: =TEXT(Table1[[#This Row],[order_time]],"HH") -> 18 | F127: 129 | G127: =_xlfn.XLOOKUP(F127,menu_items!$A$1:$A$33,menu_items!$B$1:$B$33,,0,1) -> Mushroom Ravioli | H127: =_xlfn.XLOOKUP(F127,menu_items!$A$1:$A$33,menu_items!$C$1:$C$33,,0,1) -> Italian | I127: =_xlfn.XLOOKUP(F127,menu_items!$A$1:$A$33,menu_items!$D$1:$D$33,,0,1) -> 15.5
A128: 127 | B128: 52 | C128: 44927 | D128: 0.7868287 | E128: =TEXT(Table1[[#This Row],[order_time]],"HH") -> 18 | F128: 122 | G128: =_xlfn.XLOOKUP(F128,menu_items!$A$1:$A$33,menu_items!$B$1:$B$33,,0,1) -> Chips & Salsa | H128: =_xlfn.XLOOKUP(F128,menu_items!$A$1:$A$33,menu_items!$C$1:$C$33,,0,1) -> Mexican | I128: =_xlfn.XLOOKUP(F128,menu_items!$A$1:$A$33,menu_items!$D$1:$D$33,,0,1) -> 7
A129: 128 | B129: 53 | C129: 44927 | D129: 0.78769676 | E129: =TEXT(Table1[[#This Row],[order_time]],"HH") -> 18 | F129: 112 | G129: =_xlfn.XLOOKUP(F129,menu_items!$A$1:$A$33,menu_items!$B$1:$B$33,,0,1) -> Salmon Roll | H129: =_xlfn.XLOOKUP(F129,menu_items!$A$1:$A$33,menu_items!$C$1:$C$33,,0,1) -> Asian | I129: =_xlfn.XLOOKUP(F129,menu_items!$A$1:$A$33,menu_items!$D$1:$D$33,,0,1) -> 14.95
A130: 129 | B130: 53 | C130: 44927 | D130: 0.78769676 | E130: =TEXT(Table1[[#This Row],[order_time]],"HH") -> 18 | F130: 123 | G130: =_xlfn.XLOOKUP(F130,menu_items!$A$1:$A$33,menu_items!$B$1:$B$33,,0,1) -> Chips & Guacamole | H130: =_xlfn.XLOOKUP(F130,menu_items!$A$1:$A$33,menu_items!$C$1:$C$33,,0,1) -> Mexican | I130: =_xlfn.XLOOKUP(F130,menu_items!$A$1:$A$33,menu_items!$D$1:$D$33,,0,1) -> 9
A131: 130 | B131: 54 | C131: 44927 | D131: 0.79288194 | E131: =TEXT(Table1[[#This Row],[order_time]],"HH") -> 19 | F131: 119 | G131: =_xlfn.XLOOKUP(F131,menu_items!$A$1:$A$33,menu_items!$B$1:$B$33,,0,1) -> Chicken Torta | H131: =_xlfn.XLOOKUP(F131,menu_items!$A$1:$A$33,menu_items!$C$1:$C$33,,0,1) -> Mexican | I131: =_xlfn.XLOOKUP(F131,menu_items!$A$1:$A$33,menu_items!$D$1:$D$33,,0,1) -> 11.95
A132: 131 | B132: 54 | C132: 44927 | D132: 0.79288194 | E132: =TEXT(Table1[[#This Row],[order_time]],"HH") -> 19 | F132: 106 | G132: =_xlfn.XLOOKUP(F132,menu_items!$A$1:$A$33,menu_items!$B$1:$B$33,,0,1) -> French Fries | H132: =_xlfn.XLOOKUP(F132,menu_items!$A$1:$A$33,menu_items!$C$1:$C$33,,0,1) -> American | I132: =_xlfn.XLOOKUP(F132,menu_items!$A$1:$A$33,menu_items!$D$1:$D$33,,0,1) -> 7
A133: 132 | B133: 55 | C133: 44927 | D133: 0.79396991 | E133: =TEXT(Table1[[#This Row],[order_time]],"HH") -> 19 | F133: 118 | G133: =_xlfn.XLOOKUP(F133,menu_items!$A$1:$A$33,menu_items!$B$1:$B$33,,0,1) -> Steak Burrito | H133: =_xlfn.XLOOKUP(F133,menu_items!$A$1:$A$33,menu_items!$C$1:$C$33,,0,1) -> Mexican | I133: =_xlfn.XLOOKUP(F133,menu_items!$A$1:$A$33,menu_items!$D$1:$D$33,,0,1) -> 14.95
A134: 133 | B134: 55 | C134: 44927 | D134: 0.79396991 | E134: =TEXT(Table1[[#This Row],[order_time]],"HH") -> 19 | F134: 122 | G134: =_xlfn.XLOOKUP(F134,menu_items!$A$1:$A$33,menu_items!$B$1:$B$33,,0,1) -> Chips & Salsa | H134: =_xlfn.XLOOKUP(F134,menu_items!$A$1:$A$33,menu_items!$C$1:$C$33,,0,1) -> Mexican | I134: =_xlfn.XLOOKUP(F134,menu_items!$A$1:$A$33,menu_items!$D$1:$D$33,,0,1) -> 7
A135: 134 | B135: 56 | C135: 44927 | D135: 0.79652778 | E135: =TEXT(Table1[[#This Row],[order_time]],"HH") -> 19 | F135: 108 | G135: =_xlfn.XLOOKUP(F135,menu_items!$A$1:$A$33,menu_items!$B$1:$B$33,,0,1) -> Tofu Pad Thai | H135: =_xlfn.XLOOKUP(F135,menu_items!$A$1:$A$33,menu_items!$C$1:$C$33,,0,1) -> Asian | I135: =_xlfn.XLOOKUP(F135,menu_items!$A$1:$A$33,menu_items!$D$1:$D$33,,0,1) -> 14.5
... A298: 297 | B298: 124 | C298: 44958 | D298: 0.84206019 | E298: =TEXT(Table1[[#This Row],[order_time]],"HH") -> 20 | F298: 114 | G298: =_xlfn.XLOOKUP(F298,menu_items!$A$1:$A$33,menu_items!$B$1:$B$33,,0,1) -> Potstickers | H298: =_xlfn.XLOOKUP(F298,menu_items!$A$1:$A$33,menu_items!$C$1:$C$33,,0,1) -> Asian | I298: =_xlfn.XLOOKUP(F298,menu_items!$A$1:$A$33,menu_items!$D$1:$D$33,,0,1) -> 9
A299: 298 | B299: 125 | C299: 44958 | D299: 0.85493056 | E299: =TEXT(Table1[[#This Row],[order_time]],"HH") -> 20 | F299: NULL | G299: =_xlfn.XLOOKUP(F299,menu_items!$A$1:$A$33,menu_items!$B$1:$B$33,,0,1) -> #N/A | H299: =_xlfn.XLOOKUP(F299,menu_items!$A$1:$A$33,menu_items!$C$1:$C$33,,0,1) -> #N/A | I299: =_xlfn.XLOOKUP(F299,menu_items!$A$1:$A$33,menu_items!$D$1:$D$33,,0,1) -> #N/A
A300: 299 | B300: 126 | C300: 44958 | D300: 0.870625 | E300: =TEXT(Table1[[#This Row],[order_time]],"HH") -> 20 | F300: 132 | G300: =_xlfn.XLOOKUP(F300,menu_items!$A$1:$A$33,menu_items!$B$1:$B$33,,0,1) -> Eggplant Parmesan | H300: =_xlfn.XLOOKUP(F300,menu_items!$A$1:$A$33,menu_items!$C$1:$C$33,,0,1) -> Italian | I300: =_xlfn.XLOOKUP(F300,menu_items!$A$1:$A$33,menu_items!$D$1:$D$33,,0,1) -> 16.95
A301: 300 | B301: 127 | C301: 44958 | D301: 0.87387731 | E301: =TEXT(Table1[[#This Row],[order_time]],"HH") -> 20 | F301: 113 | G301: =_xlfn.XLOOKUP(F301,menu_items!$A$1:$A$33,menu_items!$B$1:$B$33,,0,1) -> Edamame | H301: =_xlfn.XLOOKUP(F301,menu_items!$A$1:$A$33,menu_items!$C$1:$C$33,,0,1) -> Asian | I301: =_xlfn.XLOOKUP(F301,menu_items!$A$1:$A$33,menu_items!$D$1:$D$33,,0,1) -> 5
A302: 301 | B302: 128 | C302: 44958 | D302: 0.87854167 | E302: =TEXT(Table1[[#This Row],[order_time]],"HH") -> 21 | F302: 122 | G302: =_xlfn.XLOOKUP(F302,menu_items!$A$1:$A$33,menu_items!$B$1:$B$33,,0,1) -> Chips & Salsa | H302: =_xlfn.XLOOKUP(F302,menu_items!$A$1:$A$33,menu_items!$C$1:$C$33,,0,1) -> Mexican | I302: =_xlfn.XLOOKUP(F302,menu_items!$A$1:$A$33,menu_items!$D$1:$D$33,,0,1) -> 7
A303: 302 | B303: 129 | C303: 44958 | D303: 0.88405093 | E303: =TEXT(Table1[[#This Row],[order_time]],"HH") -> 21 | F303: 107 | G303: =_xlfn.XLOOKUP(F303,menu_items!$A$1:$A$33,menu_items!$B$1:$B$33,,0,1) -> Orange Chicken | H303: =_xlfn.XLOOKUP(F303,menu_items!$A$1:$A$33,menu_items!$C$1:$C$33,,0,1) -> Asian | I303: =_xlfn.XLOOKUP(F303,menu_items!$A$1:$A$33,menu_items!$D$1:$D$33,,0,1) -> 16.5
A304: 303 | B304: 129 | C304: 44958 | D304: 0.88405093 | E304: =TEXT(Table1[[#This Row],[order_time]],"HH") -> 21 | F304: 114 | G304: =_xlfn.XLOOKUP(F304,menu_items!$A$1:$A$33,menu_items!$B$1:$B$33,,0,1) -> Potstickers | H304: =_xlfn.XLOOKUP(F304,menu_items!$A$1:$A$33,menu_items!$C$1:$C$33,,0,1) -> Asian | I304: =_xlfn.XLOOKUP(F304,menu_items!$A$1:$A$33,menu_items!$D$1:$D$33,,0,1) -> 9
A305: 304 | B305: 130 | C305: 44958 | D305: 0.8853588 | E305: =TEXT(Table1[[#This Row],[order_time]],"HH") -> 21 | F305: 109 | G305: =_xlfn.XLOOKUP(F305,menu_items!$A$1:$A$33,menu_items!$B$1:$B$33,,0,1) -> Korean Beef Bowl | H305: =_xlfn.XLOOKUP(F305,menu_items!$A$1:$A$33,menu_items!$C$1:$C$33,,0,1) -> Asian | I305: =_xlfn.XLOOKUP(F305,menu_items!$A$1:$A$33,menu_items!$D$1:$D$33,,0,1) -> 17.95
A306: 305 | B306: 130 | C306: 44958 | D306: 0.8853588 | E306: =TEXT(Table1[[#This Row],[order_time]],"HH") -> 21 | F306: 110 | G306: =_xlfn.XLOOKUP(F306,menu_items!$A$1:$A$33,menu_items!$B$1:$B$33,,0,1) -> Pork Ramen | H306: =_xlfn.XLOOKUP(F306,menu_items!$A$1:$A$33,menu_items!$C$1:$C$33,,0,1) -> Asian | I306: =_xlfn.XLOOKUP(F306,menu_items!$A$1:$A$33,menu_items!$D$1:$D$33,,0,1) -> 17.95
A307: 306 | B307: 130 | C307: 44958 | D307: 0.8853588 | E307: =TEXT(Table1[[#This Row],[order_time]],"HH") -> 21 | F307: 129 | G307: =_xlfn.XLOOKUP(F307,menu_items!$A$1:$A$33,menu_items!$B$1:$B$33,,0,1) -> Mushroom Ravioli | H307: =_xlfn.XLOOKUP(F307,menu_items!$A$1:$A$33,menu_items!$C$1:$C$33,,0,1) -> Italian | I307: =_xlfn.XLOOKUP(F307,menu_items!$A$1:$A$33,menu_items!$D$1:$D$33,,0,1) -> 15.5
A308: 307 | B308: 130 | C308: 44958 | D308: 0.8853588 | E308: =TEXT(Table1[[#This Row],[order_time]],"HH") -> 21 | F308: 105 | G308: =_xlfn.XLOOKUP(F308,menu_items!$A$1:$A$33,menu_items!$B$1:$B$33,,0,1) -> Mac & Cheese | H308: =_xlfn.XLOOKUP(F308,menu_items!$A$1:$A$33,menu_items!$C$1:$C$33,,0,1) -> American | I308: =_xlfn.XLOOKUP(F308,menu_items!$A$1:$A$33,menu_items!$D$1:$D$33,,0,1) -> 7
A309: 308 | B309: 131 | C309: 44958 | D309: 0.89803241 | E309: =TEXT(Table1[[#This Row],[order_time]],"HH") -> 21 | F309: 104 | G309: =_xlfn.XLOOKUP(F309,menu_items!$A$1:$A$33,menu_items!$B$1:$B$33,,0,1) -> Veggie Burger | H309: =_xlfn.XLOOKUP(F309,menu_items!$A$1:$A$33,menu_items!$C$1:$C$33,,0,1) -> American | I309: =_xlfn.XLOOKUP(F309,menu_items!$A$1:$A$33,menu_items!$D$1:$D$33,,0,1) -> 10.5
A310: 309 | B310: 131 | C310: 44958 | D310: 0.89803241 | E310: =TEXT(Table1[[#This Row],[order_time]],"HH") -> 21 | F310: 124 | G310: =_xlfn.XLOOKUP(F310,menu_items!$A$1:$A$33,menu_items!$B$1:$B$33,,0,1) -> Spaghetti | H310: =_xlfn.XLOOKUP(F310,menu_items!$A$1:$A$33,menu_items!$C$1:$C$33,,0,1) -> Italian | I310: =_xlfn.XLOOKUP(F310,menu_items!$A$1:$A$33,menu_items!$D$1:$D$33,,0,1) -> 14.5
...

Sheet menu_items
A1: item_id | B1: item_name | C1: category | D1: price
A2: 101 | B2: Hamburger | C2: American | D2: 12.95
A3: 102 | B3: Cheeseburger | C3: American | D3: 13.95
A4: 103 | B4: Hot Dog | C4: American | D4: 9
A5: 104 | B5: Veggie Burger | C5: American | D5: 10.5
A6: 105 | B6: Mac & Cheese | C6: American | D6: 7
A7: 106 | B7: French Fries | C7: American | D7: 7
A8: 107 | B8: Orange Chicken | C8: Asian | D8: 16.5
A9: 108 | B9: Tofu Pad Thai | C9: Asian | D9: 14.5
A10: 109 | B10: Korean Beef Bowl | C10: Asian | D10: 17.95
A11: 110 | B11: Pork Ramen | C11: Asian | D11: 17.95
A12: 111 | B12: California Roll | C12: Asian | D12: 11.95
A13: 112 | B13: Salmon Roll | C13: Asian | D13: 14.95
... A33: 132 | B33: Eggplant Parmesan | C33: Italian | D33: 16.95

Sheet answer
A1: Most ordered item and category | F1: Least ordered item and category
A2: item_name | B2: category | C2: Count of item_id | F2: item_name | G2: category | H2: Count of item_id
A3: Hamburger | B3: American | C3: 622 | F3: Chicken Tacos | H3: 123
A4: Edamame | B4: Asian | C4: 620 | F4: #N/A | G4: #N/A | H4: 137
A5: Korean Beef Bowl | B5: Asian | C5: 588 | F5: Potstickers | G5: Asian | H5: 205
A6: Cheeseburger | B6: American | C6: 583 | F6: Cheese Lasagna | G6: Italian | H6: 207
A7: French Fries | B7: American | C7: 571 | F7: Steak Tacos | G7: Mexican | H7: 214
A8: Tofu Pad Thai | B8: Asian | C8: 562 | F8: Cheese Quesadillas | G8: Mexican | H8: 233
A9: Steak Torta | B9: Mexican | C9: 489 | F9: Chips & Guacamole | G9: Mexican | H9: 237
A10: Spaghetti & Meatballs | B10: Italian | C10: 470 | F10: Veggie Burger | G10: American | H10: 238
A11: Mac & Cheese | B11: American | C11: 463 | F11: Shrimp Scampi | G11: Italian | H11: 239
A12: Chips & Salsa | B12: Mexican | C12: 461 | F12: Fettuccine Alfredo | G12: Italian | H12: 249
A15: Highest spend order and what they order
A16: Row Labels | B16: Sum of price
A17: 440 | B17: 192.15
A18: Chicken Parmesan | B18: 17.95
A19: Chips & Salsa | B19: 7
A20: Edamame | B20: 5
A21: Eggplant Parmesan | B21: 16.95
A22: Fettuccine Alfredo | B22: 29
A23: French Fries | B23: 7
A24: Hot Dog | B24: 9
A25: Korean Beef Bowl | B25: 17.95
A26: Meat Lasagna | B26: 17.95
A27: Spaghetti | B27: 14.5
A28: Spaghetti & Meatballs | B28: 35.9
A29: Steak Tacos | B29: 13.95
A30: 2075 | B30: 191.05
A31: 1957 | B31: 190.1
A32: 330 | B32: 189.7
A33: 2675 | B33: 185.1
A34: 1274 | B34: 183.55
A35: 2188 | B35: 182.65
A36: 3473 | B36: 182.55
A37: 3583 | B37: 179.6
A38: 4836 | B38: 177.2
A40: Most and less order by hour
A41: Row Labels | B41: Count of order_id
A42: 12 | B42: 1672
A43: 13 | B43: 1575
...
